Traceback (most recent call last):
  File "/usr/local/lib/python3.5/dist-packages/pymongo/pool.py", line 357, in get_socket
    sock_info, from_pool = self.sockets.pop(), True
KeyError: 'pop from an empty set'

During handling of the above exception, another exception occurred:

Traceback (most recent call last):
  File "application.py", line 4, in <module>
    import dbaccesslibUserInfo as dbaUI
  File "/home/test/FlaskAPP/dbaccesslibUserInfo.py", line 13, in <module>
    client = pymongo.MongoClient(uri)
  File "/usr/local/lib/python3.5/dist-packages/pymongo/mongo_client.py", line 375, in __init__
    self._ensure_connected(True)
  File "/usr/local/lib/python3.5/dist-packages/pymongo/mongo_client.py", line 940, in _ensure_connected
    self.__ensure_member()
  File "/usr/local/lib/python3.5/dist-packages/pymongo/mongo_client.py", line 814, in __ensure_member
    member, nodes = self.__find_node()
  File "/usr/local/lib/python3.5/dist-packages/pymongo/mongo_client.py", line 874, in __find_node
    member, nodes = self.__try_node(candidate)
  File "/usr/local/lib/python3.5/dist-packages/pymongo/mongo_client.py", line 717, in __try_node
    sock_info = connection_pool.get_socket()
  File "/usr/local/lib/python3.5/dist-packages/pymongo/pool.py", line 361, in get_socket
    sock_info, from_pool = self.connect(), False
  File "/usr/local/lib/python3.5/dist-packages/pymongo/pool.py", line 288, in connect
    sock = self.create_connection()
  File "/usr/local/lib/python3.5/dist-packages/pymongo/pool.py", line 267, in create_connection
    sock.connect(sa)
KeyboardInterrupt
Traceback (most recent call last):
  File "/usr/local/lib/python3.5/dist-packages/pymongo/mongo_client.py", line 375, in __init__
    self._ensure_connected(True)
  File "/usr/local/lib/python3.5/dist-packages/pymongo/mongo_client.py", line 940, in _ensure_connected
    self.__ensure_member()
  File "/usr/local/lib/python3.5/dist-packages/pymongo/mongo_client.py", line 814, in __ensure_member
    member, nodes = self.__find_node()
  File "/usr/local/lib/python3.5/dist-packages/pymongo/mongo_client.py", line 905, in __find_node
    raise AutoReconnect(', '.join(errors))
pymongo.errors.AutoReconnect: [Errno -3] Temporary failure in name resolution

During handling of the above exception, another exception occurred:

Traceback (most recent call last):
  File "application.py", line 4, in <module>
    import dbaccesslibUserInfo as dbaUI
  File "/home/test/FlaskAPP/dbaccesslibUserInfo.py", line 13, in <module>
    client = pymongo.MongoClient(uri)
  File "/usr/local/lib/python3.5/dist-packages/pymongo/mongo_client.py", line 378, in __init__
    raise ConnectionFailure(str(e))
pymongo.errors.ConnectionFailure: [Errno -3] Temporary failure in name resolution
Traceback (most recent call last):
  File "/usr/local/lib/python3.5/dist-packages/pymongo/mongo_client.py", line 375, in __init__
    self._ensure_connected(True)
  File "/usr/local/lib/python3.5/dist-packages/pymongo/mongo_client.py", line 940, in _ensure_connected
    self.__ensure_member()
  File "/usr/local/lib/python3.5/dist-packages/pymongo/mongo_client.py", line 814, in __ensure_member
    member, nodes = self.__find_node()
  File "/usr/local/lib/python3.5/dist-packages/pymongo/mongo_client.py", line 905, in __find_node
    raise AutoReconnect(', '.join(errors))
pymongo.errors.AutoReconnect: [Errno -3] Temporary failure in name resolution

During handling of the above exception, another exception occurred:

Traceback (most recent call last):
  File "application.py", line 4, in <module>
    import dbaccesslibUserInfo as dbaUI
  File "/home/test/FlaskAPP/dbaccesslibUserInfo.py", line 13, in <module>
    client = pymongo.MongoClient(uri)
  File "/usr/local/lib/python3.5/dist-packages/pymongo/mongo_client.py", line 378, in __init__
    raise ConnectionFailure(str(e))
pymongo.errors.ConnectionFailure: [Errno -3] Temporary failure in name resolution
