 * Serving Flask app "application" (lazy loading)
 * Environment: production
   WARNING: This is a development server. Do not use it in a production deployment.
   Use a production WSGI server instead.
 * Debug mode: on
 * Serving Flask app "application" (lazy loading)
 * Environment: production
   WARNING: This is a development server. Do not use it in a production deployment.
   Use a production WSGI server instead.
 * Debug mode: on
 * Running on http://0.0.0.0:5000/ (Press CTRL+C to quit)
 * Restarting with stat
 * Debugger is active!
 * Debugger PIN: 120-406-930
10.188.103.150 - - [20/Jun/2019 19:46:55] "[37mGET / HTTP/1.1[0m" 200 -
10.188.103.150 - - [20/Jun/2019 19:47:01] "[1m[35mPOST /predict_out HTTP/1.1[0m" 500 -
Traceback (most recent call last):
  File "/usr/local/lib/python3.5/dist-packages/flask/app.py", line 2328, in __call__
    return self.wsgi_app(environ, start_response)
  File "/usr/local/lib/python3.5/dist-packages/flask/app.py", line 2314, in wsgi_app
    response = self.handle_exception(e)
  File "/usr/local/lib/python3.5/dist-packages/flask/app.py", line 1760, in handle_exception
    reraise(exc_type, exc_value, tb)
  File "/usr/local/lib/python3.5/dist-packages/flask/_compat.py", line 36, in reraise
    raise value
  File "/usr/local/lib/python3.5/dist-packages/flask/app.py", line 2311, in wsgi_app
    response = self.full_dispatch_request()
  File "/usr/local/lib/python3.5/dist-packages/flask/app.py", line 1834, in full_dispatch_request
    rv = self.handle_user_exception(e)
  File "/usr/local/lib/python3.5/dist-packages/flask/app.py", line 1737, in handle_user_exception
    reraise(exc_type, exc_value, tb)
  File "/usr/local/lib/python3.5/dist-packages/flask/_compat.py", line 36, in reraise
    raise value
  File "/usr/local/lib/python3.5/dist-packages/flask/app.py", line 1832, in full_dispatch_request
    rv = self.dispatch_request()
  File "/usr/local/lib/python3.5/dist-packages/flask/app.py", line 1818, in dispatch_request
    return self.view_functions[rule.endpoint](**req.view_args)
  File "/home/test/FlaskAPP/application.py", line 23, in predict_out
    return_val = dba.write_ontoDB(id_user,name)
  File "/home/test/FlaskAPP/dbaccesslib.py", line 13, in write_ontoDB
    conn.execute(sqlquery)
sqlite3.IntegrityError: UNIQUE constraint failed: Test_id.ID
10.188.103.150 - - [20/Jun/2019 19:47:09] "[1m[35mGET /GetDBContents HTTP/1.1[0m" 500 -
10.188.103.150 - - [20/Jun/2019 19:47:09] "[37mGET /GetDBContents?__debugger__=yes&cmd=resource&f=jquery.js HTTP/1.1[0m" 200 -
10.188.103.150 - - [20/Jun/2019 19:47:09] "[37mGET /GetDBContents?__debugger__=yes&cmd=resource&f=style.css HTTP/1.1[0m" 200 -
10.188.103.150 - - [20/Jun/2019 19:47:09] "[37mGET /GetDBContents?__debugger__=yes&cmd=resource&f=debugger.js HTTP/1.1[0m" 200 -
10.188.103.150 - - [20/Jun/2019 19:47:09] "[37mGET /GetDBContents?__debugger__=yes&cmd=resource&f=console.png HTTP/1.1[0m" 200 -
10.188.103.150 - - [20/Jun/2019 19:47:09] "[37mGET /GetDBContents?__debugger__=yes&cmd=resource&f=ubuntu.ttf HTTP/1.1[0m" 200 -
10.188.103.150 - - [20/Jun/2019 19:47:09] "[37mGET /GetDBContents?__debugger__=yes&cmd=resource&f=console.png HTTP/1.1[0m" 200 -
Insert into Test_id Values(1,'sadsad');
Traceback (most recent call last):
  File "/usr/local/lib/python3.5/dist-packages/flask/app.py", line 2328, in __call__
    return self.wsgi_app(environ, start_response)
  File "/usr/local/lib/python3.5/dist-packages/flask/app.py", line 2314, in wsgi_app
    response = self.handle_exception(e)
  File "/usr/local/lib/python3.5/dist-packages/flask/app.py", line 1760, in handle_exception
    reraise(exc_type, exc_value, tb)
  File "/usr/local/lib/python3.5/dist-packages/flask/_compat.py", line 36, in reraise
    raise value
  File "/usr/local/lib/python3.5/dist-packages/flask/app.py", line 2311, in wsgi_app
    response = self.full_dispatch_request()
  File "/usr/local/lib/python3.5/dist-packages/flask/app.py", line 1834, in full_dispatch_request
    rv = self.handle_user_exception(e)
  File "/usr/local/lib/python3.5/dist-packages/flask/app.py", line 1737, in handle_user_exception
    reraise(exc_type, exc_value, tb)
  File "/usr/local/lib/python3.5/dist-packages/flask/_compat.py", line 36, in reraise
    raise value
  File "/usr/local/lib/python3.5/dist-packages/flask/app.py", line 1832, in full_dispatch_request
    rv = self.dispatch_request()
  File "/usr/local/lib/python3.5/dist-packages/flask/app.py", line 1818, in dispatch_request
    return self.view_functions[rule.endpoint](**req.view_args)
  File "/home/test/FlaskAPP/application.py", line 28, in GetDBContents
    return_val = dba.read_fromDB()
  File "/home/test/FlaskAPP/dbaccesslib.py", line 21, in read_fromDB
    conn.close_all()
AttributeError: 'sqlite3.Connection' object has no attribute 'close_all'
 * Serving Flask app "application" (lazy loading)
 * Environment: production
   WARNING: This is a development server. Do not use it in a production deployment.
   Use a production WSGI server instead.
 * Debug mode: on
 * Running on http://0.0.0.0:5000/ (Press CTRL+C to quit)
 * Restarting with stat
 * Debugger is active!
 * Debugger PIN: 120-406-930
10.188.103.150 - - [21/Jun/2019 11:18:58] "[37mGET / HTTP/1.1[0m" 200 -
10.188.103.150 - - [21/Jun/2019 11:18:58] "[37mGET /static/js/jquery-3.4.1.min.js HTTP/1.1[0m" 200 -
10.188.103.150 - - [21/Jun/2019 11:18:58] "[37mGET /static/css/bootstrap.min.css HTTP/1.1[0m" 200 -
10.188.103.150 - - [21/Jun/2019 11:18:58] "[37mGET /static/js/bootstrap.min.js HTTP/1.1[0m" 200 -
10.188.103.150 - - [21/Jun/2019 11:19:06] "[1m[35mPOST /predict_out HTTP/1.1[0m" 500 -
Traceback (most recent call last):
  File "/usr/local/lib/python3.5/dist-packages/flask/app.py", line 2328, in __call__
    return self.wsgi_app(environ, start_response)
  File "/usr/local/lib/python3.5/dist-packages/flask/app.py", line 2314, in wsgi_app
    response = self.handle_exception(e)
  File "/usr/local/lib/python3.5/dist-packages/flask/app.py", line 1760, in handle_exception
    reraise(exc_type, exc_value, tb)
  File "/usr/local/lib/python3.5/dist-packages/flask/_compat.py", line 36, in reraise
    raise value
  File "/usr/local/lib/python3.5/dist-packages/flask/app.py", line 2311, in wsgi_app
    response = self.full_dispatch_request()
  File "/usr/local/lib/python3.5/dist-packages/flask/app.py", line 1835, in full_dispatch_request
    return self.finalize_request(rv)
  File "/usr/local/lib/python3.5/dist-packages/flask/app.py", line 1850, in finalize_request
    response = self.make_response(rv)
  File "/usr/local/lib/python3.5/dist-packages/flask/app.py", line 1968, in make_response
    'The view function did not return a valid response tuple.'
TypeError: The view function did not return a valid response tuple. The tuple must have the form (body, status, headers), (body, status), or (body, headers).
10.188.103.150 - - [21/Jun/2019 11:19:09] "[37mGET /GetDBContents HTTP/1.1[0m" 200 -
10.188.103.150 - - [21/Jun/2019 11:19:14] "[1m[35mPOST /predict_out HTTP/1.1[0m" 500 -
10.188.103.150 - - [21/Jun/2019 11:19:17] "[37mGET /GetDBContents HTTP/1.1[0m" 200 -
